<mujoco model="panda">
    <option timestep="0.1" integrator="RK4" gravity="0 0 -9.81" >
		<flag sensornoise="disable" energy="enable" contact="enable" />
	</option>
    <compiler angle="radian" />
    <size njmax="500" nconmax="100" />
    <worldbody>
        <geom size="0.09 0.015" pos="-0.075 0 0.06" quat="0.707107 0 0.707107 0" type="cylinder" />
        <geom size="0.09" pos="-0.06 0 0.06" />
        <geom size="0.09" pos="-0.09 0 0.06" />
        <body name="panda_link1" pos="0 0 0.333">
            <inertial pos="0 0 -0.1915" mass="13.3087" diaginertia="0.204715 0.204715 0.0489535" />
            <joint name="panda_joint1" pos="0 0 0" axis="0 0 1" limited="true" range="-2.8973 2.8973" />
            <geom size="0.09 0.1415" pos="0 0 -0.1915" type="cylinder" />
            <geom size="0.09" pos="0 0 -0.333" />
            <geom size="0.09" pos="0 0 -0.05" />
            <body name="panda_link2" pos="0 0 0" quat="0.707107 -0.707107 0 0">
                <inertial pos="0 0 0" mass="9.16088" diaginertia="0.0516216 0.0516216 0.0321547" />
                <joint name="panda_joint2" pos="0 0 0" axis="0 0 1" limited="true" range="-1.7628 1.7628" />
                <geom size="0.09 0.06" type="cylinder" />
                <geom size="0.09" pos="0 0 -0.06" />
                <geom size="0.09" pos="0 0 0.06" />
                <body name="panda_link3" pos="0 -0.316 0" quat="0.707107 0.707107 0 0">
                    <inertial pos="0 0 -0.145" mass="9.92429" diaginertia="0.0690273 0.0690273 0.0352465" />
                    <joint name="panda_joint3" pos="0 0 0" axis="0 0 1" limited="true" range="-2.8973 2.8973" />
                    <geom size="0.09 0.075" pos="0 0 -0.145" type="cylinder" />
                    <geom size="0.09" pos="0 0 -0.22" />
                    <geom size="0.09" pos="0 0 -0.07" />
                    <body name="panda_link4" pos="0.0825 0 0" quat="0.707107 0.707107 0 0">
                        <inertial pos="0 0 0" mass="9.16088" diaginertia="0.0516216 0.0516216 0.0321547" />
                        <joint name="panda_joint4" pos="0 0 0" axis="0 0 1" limited="true" range="-3.0718 -0.0698" />
                        <geom size="0.09 0.06" type="cylinder" />
                        <geom size="0.09" pos="0 0 0.06" />
                        <geom size="0.09" pos="0 0 -0.06" />
                        <body name="panda_link5" pos="-0.0825 0.384 0" quat="0.707107 -0.707107 0 0">
                            <inertial pos="0 0.0191577 -0.228869" quat="0.980145 -0.198283 0 0" mass="11.3762" diaginertia="0.1023 0.0981299 0.0379623" />
                            <joint name="panda_joint5" pos="0 0 0" axis="0 0 1" limited="true" range="-2.8973 2.8973" />
                            <geom size="0.09 0.05" pos="0 0 -0.26" type="cylinder" />
                            <geom size="0.09" pos="0 0 -0.31" />
                            <geom size="0.09" pos="0 0 -0.21" />
                            <geom size="0.055 0.07" pos="0 0.08 -0.13" type="cylinder" />
                            <geom size="0.055" pos="0 0.08 -0.06" />
                            <geom size="0.055" pos="0 0.08 -0.2" />
                            <body name="panda_link6" pos="0 0 0" quat="0.707107 0.707107 0 0">
                                <inertial pos="0 0 -0.03" mass="5.89782" diaginertia="0.021275 0.021275 0.0161278" />
                                <joint name="panda_joint6" pos="0 0 0" axis="0 0 1" limited="true" range="-0.0175 3.7525" />
                                <geom size="0.08 0.04" pos="0 0 -0.03" type="cylinder" />
                                <geom size="0.08" pos="0 0 0.01" />
                                <geom size="0.08" pos="0 0 -0.07" />
                                <body name="panda_link7" pos="0.088 0 0" quat="0.707107 0.707107 0 0">
                                    <inertial pos="0.0117274 0.0117274 0.0299144" quat="0.910272 -0.140164 0.0571282 -0.385351" mass="6.9513" diaginertia="0.0408884 0.0377691 0.0167385" />
                                    <joint name="panda_joint7" pos="0 0 0" axis="0 0 1" limited="true" range="-2.8973 2.8973" />
                                    <geom size="0.07 0.07" pos="0 0 0.01" type="cylinder" />
                                    <geom size="0.07" pos="0 0 0.08" />
                                    <geom size="0.07" pos="0 0 -0.06" />
                                    <geom size="0.06 0.005" pos="0.0424 0.0424 0.082" quat="0.5 0.5 0.5 -0.5" type="cylinder" />
                                    <geom size="0.06" pos="0.0424 0.0424 0.087" />
                                    <geom size="0.06" pos="0.0424 0.0424 0.077" />
                                    <site name="endeff" pos="0 0 0.15" rgba="0 0 .9 1" size="0.05"/>
                                </body>
                            </body>
                        </body>
                    </body>
                </body>
            </body>
        </body>
    </worldbody>

    <contact>
        <exclude body1="world" body2="panda_link1"/>
        <exclude body1="world" body2="panda_link2"/>
        <exclude body1="world" body2="panda_link3"/>
        <exclude body1="world" body2="panda_link4"/>
        <exclude body1="world" body2="panda_link5"/>
        <exclude body1="world" body2="panda_link6"/>
        <exclude body1="world" body2="panda_link7"/>
        <exclude body1="panda_link1" body2="panda_link2"/>
        <exclude body1="panda_link1" body2="panda_link3"/>
        <exclude body1="panda_link1" body2="panda_link4"/>
        <exclude body1="panda_link1" body2="panda_link5"/>
        <exclude body1="panda_link1" body2="panda_link6"/>
        <exclude body1="panda_link1" body2="panda_link7"/>
        <exclude body1="panda_link2" body2="panda_link3"/>
        <exclude body1="panda_link2" body2="panda_link4"/>
        <exclude body1="panda_link2" body2="panda_link5"/>
        <exclude body1="panda_link2" body2="panda_link6"/>
        <exclude body1="panda_link2" body2="panda_link7"/>
        <exclude body1="panda_link3" body2="panda_link4"/>
        <exclude body1="panda_link3" body2="panda_link5"/>
        <exclude body1="panda_link3" body2="panda_link6"/>
        <exclude body1="panda_link3" body2="panda_link7"/>
        <exclude body1="panda_link4" body2="panda_link5"/>
        <exclude body1="panda_link4" body2="panda_link6"/>
        <exclude body1="panda_link4" body2="panda_link7"/>
        <exclude body1="panda_link5" body2="panda_link6"/>
        <exclude body1="panda_link5" body2="panda_link7"/>
        <exclude body1="panda_link6" body2="panda_link7"/>
    </contact>

    <!-- <actuator>
		<position name="pservo1" joint="panda_joint1" kp="1000" />
		<velocity name="vservo1" joint="panda_joint1" kv="100" />
		<position name="pservo2" joint="panda_joint2" kp="1000" />
		<velocity name="vservo2" joint="panda_joint2" kv="100" />
        <position name="pservo3" joint="panda_joint3" kp="1000" />
		<velocity name="vservo3" joint="panda_joint3" kv="100" />
        <position name="pservo4" joint="panda_joint4" kp="1000" />
		<velocity name="vservo4" joint="panda_joint4" kv="100" />
        <position name="pservo5" joint="panda_joint5" kp="1000" />
		<velocity name="vservo5" joint="panda_joint5" kv="100" />
        <position name="pservo6" joint="panda_joint6" kp="1000" />
		<velocity name="vservo6" joint="panda_joint6" kv="100" />
        <position name="pservo7" joint="panda_joint7" kp="1000" />
		<velocity name="vservo7" joint="panda_joint7" kv="100" />
	</actuator> -->

    <sensor>
		<framepos objtype="site" objname="endeff"/>
		<framelinvel objtype="site" objname="endeff"/>
        <frameangvel objtype="site" objname="endeff"/>
        <framelinacc objtype="site" objname="endeff"/>
        <frameangacc objtype="site" objname="endeff"/>
	</sensor>
</mujoco>
