<mujoco model="box">
    <compiler angle="radian" meshdir="box/stl/" autolimits="true" />
    <default />
    <asset>
        <mesh name="BoxFlap1" file="BoxFlap1.stl" />
        <mesh name="BoxFlap2" file="BoxFlap2.stl" />
    </asset>
    <worldbody>
        <body name="box" gravcomp="0">
            <geom size="0.17 0.16 0.0025" pos="0 0 -0.1675" type="box" rgba="1 0.8 0 1"/>
            <geom size="0.002578 0.16 0.1675" pos="0.167578 0 -0.0025" type="box" rgba="1 0.8 0 1"/>
            <geom size="0.002578 0.16 0.1675" pos="-0.167578 0 -0.0025" type="box" rgba="1 0.8 0 1"/>
            <geom size="0.170156 0.0025 0.1675" pos="0 0.1575 -0.0025" type="box" rgba="1 0.8 0 1"/>
            <geom size="0.170156 0.0025 0.1675" pos="0 -0.1575 -0.0025" type="box" rgba="1 0.8 0 1"/>
            <body name="box_flap_1" pos="0.17 0 0.166" gravcomp="0">
                <joint name="box_flap_1_joint" pos="0 0 0" axis="0 1 0" range="-1.57 4.7"/>
                <geom type="mesh" mesh="BoxFlap1" rgba="1 0.8 0 1"/>
            </body>
            <body name="box_flap_2" pos="-0.17 0 0.168" gravcomp="0">
                <joint name="box_flap_2_joint" pos="0 0 0" axis="0 -1 0" range="-1.57 4.7"/>
                <geom type="mesh" mesh="BoxFlap2" rgba="1 0.8 0 1"/>
            </body>
        </body>
    </worldbody>
    <equality/>
    <contact>
        <exclude body1="box" body2="box_flap_1"/>
        <exclude body1="box" body2="box_flap_2"/>
    </contact>
</mujoco>