<mujoco model="box">
    <compiler angle="radian" meshdir="box/stl/" autolimits="true" />
    <default />
    <asset>
        <mesh name="BoxFlap1" file="BoxFlap1.stl" />
        <mesh name="BoxFlap2" file="BoxFlap2.stl" />
    </asset>
    <worldbody>
        <body name="box" pos="0 0 2">
            <freejoint />
            <body name="box_corpus">
                <geom size="0.17 0.16 0.0025" pos="0 0 -0.1675" type="box" />
                <geom size="0.002578 0.16 0.1675" pos="0.167578 0 -0.0025" type="box" />
                <geom size="0.002578 0.16 0.1675" pos="-0.167578 0 -0.0025" type="box" />
                <geom size="0.170156 0.0025 0.1675" pos="0 0.1575 -0.0025" type="box" />
                <geom size="0.170156 0.0025 0.1675" pos="0 -0.1575 -0.0025" type="box" />
            </body>
            <body name="box_flap_1" pos="0.17 0 0.166" gravcomp="0">
                <joint name="box_flap_1_joint" axis="0 1 0" stiffness="0.1" damping="0.1" />
                <geom type="mesh" mesh="BoxFlap1" />
            </body>
            <body name="box_flap_2" pos="-0.17 0 0.168" gravcomp="0">
                <joint name="box_flap_2_joint" axis="0 -1 0" stiffness="0.1" damping="0.1" />
                <geom type="mesh" mesh="BoxFlap2" />
            </body>
        </body>
    </worldbody>
    <equality />
    <contact />
</mujoco>